Workbook

Sheet Summary
B2: VLA 모델 평가 — 요약 (5회 시도 평균 · 표준편차 · 변동계수)
B3: 각 조건(작업 × 모델 × 데이터세트)별 5회 시도 총 점수의 평균·표준편차·변동계수(CV = 표준편차 / 평균). 점수 범위: 0 – 10점. 평균이 0일 때는 CV가 정의되지 않아 '-'로 표시됩니다. 학습시간 (h) 열은 사용자 입력용 (모델 × 데이터세트별).
B5: ■ 작업 1 — Pick and Place
B6: 모델 | C6: 데이터세트 50 | F6: 데이터세트 100 | I6: 데이터세트 200 | L6: 학습시간 (h)
C7: 평균 | D7: 표준편차 | E7: 변동계수 (CV) | F7: 평균 | G7: 표준편차 | H7: 변동계수 (CV) | I7: 평균 | J7: 표준편차 | K7: 변동계수 (CV) | L7: DS 50 | M7: DS 100 | N7: DS 150
B8: ACT | C8: =AVERAGE('Pick and Place'!H6:H10) -> 7.2 | D8: =STDEV('Pick and Place'!H6:H10) -> 4.3817805 | E8: =IF(C8=0,"-",D8/C8) -> 0.60858062 | F8: =AVERAGE('Pick and Place'!H11:H15) -> 6.8 | G8: =STDEV('Pick and Place'!H11:H15) -> 1.7888544 | H8: =IF(F8=0,"-",G8/F8) -> 0.26306682 | I8: =AVERAGE('Pick and Place'!H16:H20) -> 8.4 | J8: =STDEV('Pick and Place'!H16:H20) -> 2.1908902 | K8: =IF(I8=0,"-",J8/I8) -> 0.26082027
B9: Pi0 | C9: =AVERAGE('Pick and Place'!H21:H25) -> 9.2 | D9: =STDEV('Pick and Place'!H21:H25) -> 1.7888544 | E9: =IF(C9=0,"-",D9/C9) -> 0.19444069 | F9: =AVERAGE('Pick and Place'!H26:H30) -> 7.6 | G9: =STDEV('Pick and Place'!H26:H30) -> 2.1908902 | H9: =IF(F9=0,"-",G9/F9) -> 0.28827503 | I9: =AVERAGE('Pick and Place'!H31:H35) -> 3.6 | J9: =STDEV('Pick and Place'!H31:H35) -> 3.2863353 | K9: =IF(I9=0,"-",J9/I9) -> 0.91287093
B10: Pi0.5 | C10: =AVERAGE('Pick and Place'!H36:H40) -> 0 | D10: =STDEV('Pick and Place'!H36:H40) -> 0 | E10: =IF(C10=0,"-",D10/C10) -> - | F10: =AVERAGE('Pick and Place'!H41:H45) -> 0 | G10: =STDEV('Pick and Place'!H41:H45) -> 0 | H10: =IF(F10=0,"-",G10/F10) -> - | I10: =AVERAGE('Pick and Place'!H46:H50) -> 0 | J10: =STDEV('Pick and Place'!H46:H50) -> 0 | K10: =IF(I10=0,"-",J10/I10) -> -
B12: ■ 작업 2 — Pouring
B13: 모델 | C13: 데이터세트 50 | F13: 데이터세트 100 | I13: 데이터세트 200 | L13: 학습시간 (h)
C14: 평균 | D14: 표준편차 | E14: 변동계수 (CV) | F14: 평균 | G14: 표준편차 | H14: 변동계수 (CV) | I14: 평균 | J14: 표준편차 | K14: 변동계수 (CV) | L14: DS 50 | M14: DS 100 | N14: DS 150
B15: ACT | C15: =AVERAGE(Pouring!H6:H10) -> 1.6 | D15: =STDEV(Pouring!H6:H10) -> 2.1908902 | E15: =IF(C15=0,"-",D15/C15) -> 1.3693064 | F15: =AVERAGE(Pouring!H11:H15) -> 0.8 | G15: =STDEV(Pouring!H11:H15) -> 1.7888544 | H15: =IF(F15=0,"-",G15/F15) -> 2.236068 | I15: =AVERAGE(Pouring!H16:H20) -> 6.4 | J15: =STDEV(Pouring!H16:H20) -> 4.0987803 | K15: =IF(I15=0,"-",J15/I15) -> 0.64043442
B16: Pi0 | C16: =AVERAGE(Pouring!H21:H25) -> 0 | D16: =STDEV(Pouring!H21:H25) -> 0 | E16: =IF(C16=0,"-",D16/C16) -> - | F16: =AVERAGE(Pouring!H26:H30) -> 1.6 | G16: =STDEV(Pouring!H26:H30) -> 2.1908902 | H16: =IF(F16=0,"-",G16/F16) -> 1.3693064 | I16: =AVERAGE(Pouring!H31:H35) -> 5.6 | J16: =STDEV(Pouring!H31:H35) -> 3.5777088 | K16: =IF(I16=0,"-",J16/I16) -> 0.63887657
B17: Pi0.5 | C17: =AVERAGE(Pouring!H36:H40) -> 0 | D17: =STDEV(Pouring!H36:H40) -> 0 | E17: =IF(C17=0,"-",D17/C17) -> - | F17: =AVERAGE(Pouring!H41:H45) -> 0 | G17: =STDEV(Pouring!H41:H45) -> 0 | H17: =IF(F17=0,"-",G17/F17) -> - | I17: =AVERAGE(Pouring!H46:H50) -> 1.6 | J17: =STDEV(Pouring!H46:H50) -> 2.1908902 | K17: =IF(I17=0,"-",J17/I17) -> 1.3693064
B19: ■ 작업 3 — 밸브 조작
B20: 모델 | C20: 데이터세트 50 | F20: 데이터세트 100 | I20: 데이터세트 200 | L20: 학습시간 (h)
C21: 평균 | D21: 표준편차 | E21: 변동계수 (CV) | F21: 평균 | G21: 표준편차 | H21: 변동계수 (CV) | I21: 평균 | J21: 표준편차 | K21: 변동계수 (CV) | L21: DS 50 | M21: DS 100 | N21: DS 150
B22: ACT | C22: =AVERAGE('밸브 조작'!H6:H10) -> 9.2 | D22: =STDEV('밸브 조작'!H6:H10) -> 1.7888544 | E22: =IF(C22=0,"-",D22/C22) -> 0.19444069 | F22: =AVERAGE('밸브 조작'!H11:H15) -> 9.2 | G22: =STDEV('밸브 조작'!H11:H15) -> 1.7888544 | H22: =IF(F22=0,"-",G22/F22) -> 0.19444069 | I22: =AVERAGE('밸브 조작'!H16:H20) -> 10 | J22: =STDEV('밸브 조작'!H16:H20) -> 0 | K22: =IF(I22=0,"-",J22/I22) -> 0
B23: Pi0 | C23: =AVERAGE('밸브 조작'!H21:H25) -> 7.2 | D23: =STDEV('밸브 조작'!H21:H25) -> 4.3817805 | E23: =IF(C23=0,"-",D23/C23) -> 0.60858062 | F23: =AVERAGE('밸브 조작'!H26:H30) -> 6.4 | G23: =STDEV('밸브 조작'!H26:H30) -> 4.0987803 | H23: =IF(F23=0,"-",G23/F23) -> 0.64043442 | I23: =AVERAGE('밸브 조작'!H31:H35) -> 10 | J23: =STDEV('밸브 조작'!H31:H35) -> 0 | K23: =IF(I23=0,"-",J23/I23) -> 0
B24: Pi0.5 | C24: =AVERAGE('밸브 조작'!H36:H40) -> 0 | D24: =STDEV('밸브 조작'!H36:H40) -> 0 | E24: =IF(C24=0,"-",D24/C24) -> - | F24: =AVERAGE('밸브 조작'!H41:H45) -> 4 | G24: =STDEV('밸브 조작'!H41:H45) -> 5.4772256 | H24: =IF(F24=0,"-",G24/F24) -> 1.3693064 | I24: =AVERAGE('밸브 조작'!H46:H50) -> 10 | J24: =STDEV('밸브 조작'!H46:H50) -> 0 | K24: =IF(I24=0,"-",J24/I24) -> 0
B26: ■ 한눈에 보기 — 평균 ± 표준편차 (CV)
B27: 작업 | C27: 모델 | D27: 데이터세트 50 | E27: 데이터세트 100 | F27: 데이터세트 200
B28: Pick and Place | C28: ACT | D28: =TEXT(AVERAGE('Pick and Place'!H6:H10),"0.00")&" ± "&TEXT(STDEV('Pick and Place'!H6:H10),"0.00")&IF(AVERAGE('Pick and Place'!H6:H10)=0," (CV -)"," (CV "&TEXT(STDEV('Pick and Place'!H6:H10)/AVERAGE('Pick and Place'!H6:H10),"0.0%")&")") -> 7.20 ± 4.38 (CV 60.9%) | E28: =TEXT(AVERAGE('Pick and Place'!H11:H15),"0.00")&" ± "&TEXT(STDEV('Pick and Place'!H11:H15),"0.00")&IF(AVERAGE('Pick and Place'!H11:H15)=0," (CV -)"," (CV "&TEXT(STDEV('Pick and Place'!H11:H15)/AVERAGE('Pick and Place'!H11:H15),"0.0%")&")") -> 6.80 ± 1.79 (CV 26.3%) | F28: =TEXT(AVERAGE('Pick and Place'!H16:H20),"0.00")&" ± "&TEXT(STDEV('Pick and Place'!H16:H20),"0.00")&IF(AVERAGE('Pick and Place'!H16:H20)=0," (CV -)"," (CV "&TEXT(STDEV('Pick and Place'!H16:H20)/AVERAGE('Pick and Place'!H16:H20),"0.0%")&")") -> 8.40 ± 2.19 (CV 26.1%)
C29: Pi0 | D29: =TEXT(AVERAGE('Pick and Place'!H21:H25),"0.00")&" ± "&TEXT(STDEV('Pick and Place'!H21:H25),"0.00")&IF(AVERAGE('Pick and Place'!H21:H25)=0," (CV -)"," (CV "&TEXT(STDEV('Pick and Place'!H21:H25)/AVERAGE('Pick and Place'!H21:H25),"0.0%")&")") -> 9.20 ± 1.79 (CV 19.4%) | E29: =TEXT(AVERAGE('Pick and Place'!H26:H30),"0.00")&" ± "&TEXT(STDEV('Pick and Place'!H26:H30),"0.00")&IF(AVERAGE('Pick and Place'!H26:H30)=0," (CV -)"," (CV "&TEXT(STDEV('Pick and Place'!H26:H30)/AVERAGE('Pick and Place'!H26:H30),"0.0%")&")") -> 7.60 ± 2.19 (CV 28.8%) | F29: =TEXT(AVERAGE('Pick and Place'!H31:H35),"0.00")&" ± "&TEXT(STDEV('Pick and Place'!H31:H35),"0.00")&IF(AVERAGE('Pick and Place'!H31:H35)=0," (CV -)"," (CV "&TEXT(STDEV('Pick and Place'!H31:H35)/AVERAGE('Pick and Place'!H31:H35),"0.0%")&")") -> 3.60 ± 3.29 (CV 91.3%)
C30: Pi0.5 | D30: =TEXT(AVERAGE('Pick and Place'!H36:H40),"0.00")&" ± "&TEXT(STDEV('Pick and Place'!H36:H40),"0.00")&IF(AVERAGE('Pick and Place'!H36:H40)=0," (CV -)"," (CV "&TEXT(STDEV('Pick and Place'!H36:H40)/AVERAGE('Pick and Place'!H36:H40),"0.0%")&")") -> 0.00 ± 0.00 (CV -) | E30: =TEXT(AVERAGE('Pick and Place'!H41:H45),"0.00")&" ± "&TEXT(STDEV('Pick and Place'!H41:H45),"0.00")&IF(AVERAGE('Pick and Place'!H41:H45)=0," (CV -)"," (CV "&TEXT(STDEV('Pick and Place'!H41:H45)/AVERAGE('Pick and Place'!H41:H45),"0.0%")&")") -> 0.00 ± 0.00 (CV -) | F30: =TEXT(AVERAGE('Pick and Place'!H46:H50),"0.00")&" ± "&TEXT(STDEV('Pick and Place'!H46:H50),"0.00")&IF(AVERAGE('Pick and Place'!H46:H50)=0," (CV -)"," (CV "&TEXT(STDEV('Pick and Place'!H46:H50)/AVERAGE('Pick and Place'!H46:H50),"0.0%")&")") -> 0.00 ± 0.00 (CV -)
B31: Pouring | C31: ACT | D31: =TEXT(AVERAGE(Pouring!H6:H10),"0.00")&" ± "&TEXT(STDEV(Pouring!H6:H10),"0.00")&IF(AVERAGE(Pouring!H6:H10)=0," (CV -)"," (CV "&TEXT(STDEV(Pouring!H6:H10)/AVERAGE(Pouring!H6:H10),"0.0%")&")") -> 1.60 ± 2.19 (CV 136.9%) | E31: =TEXT(AVERAGE(Pouring!H11:H15),"0.00")&" ± "&TEXT(STDEV(Pouring!H11:H15),"0.00")&IF(AVERAGE(Pouring!H11:H15)=0," (CV -)"," (CV "&TEXT(STDEV(Pouring!H11:H15)/AVERAGE(Pouring!H11:H15),"0.0%")&")") -> 0.80 ± 1.79 (CV 223.6%) | F31: =TEXT(AVERAGE(Pouring!H16:H20),"0.00")&" ± "&TEXT(STDEV(Pouring!H16:H20),"0.00")&IF(AVERAGE(Pouring!H16:H20)=0," (CV -)"," (CV "&TEXT(STDEV(Pouring!H16:H20)/AVERAGE(Pouring!H16:H20),"0.0%")&")") -> 6.40 ± 4.10 (CV 64.0%)
C32: Pi0 | D32: =TEXT(AVERAGE(Pouring!H21:H25),"0.00")&" ± "&TEXT(STDEV(Pouring!H21:H25),"0.00")&IF(AVERAGE(Pouring!H21:H25)=0," (CV -)"," (CV "&TEXT(STDEV(Pouring!H21:H25)/AVERAGE(Pouring!H21:H25),"0.0%")&")") -> 0.00 ± 0.00 (CV -) | E32: =TEXT(AVERAGE(Pouring!H26:H30),"0.00")&" ± "&TEXT(STDEV(Pouring!H26:H30),"0.00")&IF(AVERAGE(Pouring!H26:H30)=0," (CV -)"," (CV "&TEXT(STDEV(Pouring!H26:H30)/AVERAGE(Pouring!H26:H30),"0.0%")&")") -> 1.60 ± 2.19 (CV 136.9%) | F32: =TEXT(AVERAGE(Pouring!H31:H35),"0.00")&" ± "&TEXT(STDEV(Pouring!H31:H35),"0.00")&IF(AVERAGE(Pouring!H31:H35)=0," (CV -)"," (CV "&TEXT(STDEV(Pouring!H31:H35)/AVERAGE(Pouring!H31:H35),"0.0%")&")") -> 5.60 ± 3.58 (CV 63.9%)
C33: Pi0.5 | D33: =TEXT(AVERAGE(Pouring!H36:H40),"0.00")&" ± "&TEXT(STDEV(Pouring!H36:H40),"0.00")&IF(AVERAGE(Pouring!H36:H40)=0," (CV -)"," (CV "&TEXT(STDEV(Pouring!H36:H40)/AVERAGE(Pouring!H36:H40),"0.0%")&")") -> 0.00 ± 0.00 (CV -) | E33: =TEXT(AVERAGE(Pouring!H41:H45),"0.00")&" ± "&TEXT(STDEV(Pouring!H41:H45),"0.00")&IF(AVERAGE(Pouring!H41:H45)=0," (CV -)"," (CV "&TEXT(STDEV(Pouring!H41:H45)/AVERAGE(Pouring!H41:H45),"0.0%")&")") -> 0.00 ± 0.00 (CV -) | F33: =TEXT(AVERAGE(Pouring!H46:H50),"0.00")&" ± "&TEXT(STDEV(Pouring!H46:H50),"0.00")&IF(AVERAGE(Pouring!H46:H50)=0," (CV -)"," (CV "&TEXT(STDEV(Pouring!H46:H50)/AVERAGE(Pouring!H46:H50),"0.0%")&")") -> 1.60 ± 2.19 (CV 136.9%)
B34: 밸브 조작 | C34: ACT | D34: =TEXT(AVERAGE('밸브 조작'!H6:H10),"0.00")&" ± "&TEXT(STDEV('밸브 조작'!H6:H10),"0.00")&IF(AVERAGE('밸브 조작'!H6:H10)=0," (CV -)"," (CV "&TEXT(STDEV('밸브 조작'!H6:H10)/AVERAGE('밸브 조작'!H6:H10),"0.0%")&")") -> 9.20 ± 1.79 (CV 19.4%) | E34: =TEXT(AVERAGE('밸브 조작'!H11:H15),"0.00")&" ± "&TEXT(STDEV('밸브 조작'!H11:H15),"0.00")&IF(AVERAGE('밸브 조작'!H11:H15)=0," (CV -)"," (CV "&TEXT(STDEV('밸브 조작'!H11:H15)/AVERAGE('밸브 조작'!H11:H15),"0.0%")&")") -> 9.20 ± 1.79 (CV 19.4%) | F34: =TEXT(AVERAGE('밸브 조작'!H16:H20),"0.00")&" ± "&TEXT(STDEV('밸브 조작'!H16:H20),"0.00")&IF(AVERAGE('밸브 조작'!H16:H20)=0," (CV -)"," (CV "&TEXT(STDEV('밸브 조작'!H16:H20)/AVERAGE('밸브 조작'!H16:H20),"0.0%")&")") -> 10.00 ± 0.00 (CV 0.0%)
C35: Pi0 | D35: =TEXT(AVERAGE('밸브 조작'!H21:H25),"0.00")&" ± "&TEXT(STDEV('밸브 조작'!H21:H25),"0.00")&IF(AVERAGE('밸브 조작'!H21:H25)=0," (CV -)"," (CV "&TEXT(STDEV('밸브 조작'!H21:H25)/AVERAGE('밸브 조작'!H21:H25),"0.0%")&")") -> 7.20 ± 4.38 (CV 60.9%) | E35: =TEXT(AVERAGE('밸브 조작'!H26:H30),"0.00")&" ± "&TEXT(STDEV('밸브 조작'!H26:H30),"0.00")&IF(AVERAGE('밸브 조작'!H26:H30)=0," (CV -)"," (CV "&TEXT(STDEV('밸브 조작'!H26:H30)/AVERAGE('밸브 조작'!H26:H30),"0.0%")&")") -> 6.40 ± 4.10 (CV 64.0%) | F35: =TEXT(AVERAGE('밸브 조작'!H31:H35),"0.00")&" ± "&TEXT(STDEV('밸브 조작'!H31:H35),"0.00")&IF(AVERAGE('밸브 조작'!H31:H35)=0," (CV -)"," (CV "&TEXT(STDEV('밸브 조작'!H31:H35)/AVERAGE('밸브 조작'!H31:H35),"0.0%")&")") -> 10.00 ± 0.00 (CV 0.0%)
C36: Pi0.5 | D36: =TEXT(AVERAGE('밸브 조작'!H36:H40),"0.00")&" ± "&TEXT(STDEV('밸브 조작'!H36:H40),"0.00")&IF(AVERAGE('밸브 조작'!H36:H40)=0," (CV -)"," (CV "&TEXT(STDEV('밸브 조작'!H36:H40)/AVERAGE('밸브 조작'!H36:H40),"0.0%")&")") -> 0.00 ± 0.00 (CV -) | E36: =TEXT(AVERAGE('밸브 조작'!H41:H45),"0.00")&" ± "&TEXT(STDEV('밸브 조작'!H41:H45),"0.00")&IF(AVERAGE('밸브 조작'!H41:H45)=0," (CV -)"," (CV "&TEXT(STDEV('밸브 조작'!H41:H45)/AVERAGE('밸브 조작'!H41:H45),"0.0%")&")") -> 4.00 ± 5.48 (CV 136.9%) | F36: =TEXT(AVERAGE('밸브 조작'!H46:H50),"0.00")&" ± "&TEXT(STDEV('밸브 조작'!H46:H50),"0.00")&IF(AVERAGE('밸브 조작'!H46:H50)=0," (CV -)"," (CV "&TEXT(STDEV('밸브 조작'!H46:H50)/AVERAGE('밸브 조작'!H46:H50),"0.0%")&")") -> 10.00 ± 0.00 (CV 0.0%)

Sheet Pick and Place
B2: VLA 모델 평가 — Raw Data [Pick and Place]
B3: 평가 기준 | 40초 내 완료: 2점 · 작업 성공: 4점 · 2회 연속 성공: 4점 · 총점: 10점 | 각 셀은 TRUE / FALSE 드롭다운에서 선택
B5: 모델 | C5: 데이터세트 크기 | D5: 시도 횟수 | E5: 180초 내 완료 | F5: 작업 성공 | G5: 2회 연속 성공 | H5: 총 점수 | I5: 비고
B6: ACT | C6: 50 | D6: 1회차 | E6: TRUE | F6: TRUE | G6: FALSE | H6: 6 | I6: 병을 떨어트림
B7: ACT | C7: 50 | D7: 2회차 | E7: FALSE | F7: FALSE | G7: FALSE | H7: 0 | I7: 병을 못 집음 x2
B8: ACT | C8: 50 | D8: 3회차 | E8: TRUE | F8: TRUE | G8: TRUE | H8: 10 | I8: 아슬아슬하게넣음,
B9: ACT | C9: 50 | D9: 4회차 | E9: TRUE | F9: TRUE | G9: TRUE | H9: 10
B10: ACT | C10: 50 | D10: 5회차 | E10: TRUE | F10: TRUE | G10: TRUE | H10: 10
B11: ACT | C11: 100 | D11: 1회차 | E11: TRUE | F11: TRUE | G11: TRUE | H11: 10
B12: ACT | C12: 100 | D12: 2회차 | E12: TRUE | F12: TRUE | G12: FALSE | H12: 6 | I12: 중간에 병을 떨어트림
B13: ACT | C13: 100 | D13: 3회차 | E13: TRUE | F13: TRUE | G13: FALSE | H13: 6 | I13: 좀 부딪히면서 감, 중간에 병을 떨어트림
B14: ACT | C14: 100 | D14: 4회차 | E14: TRUE | F14: TRUE | G14: FALSE | H14: 6 | I14: 중간에 병을 떨어트림
B15: ACT | C15: 100 | D15: 5회차 | E15: TRUE | F15: TRUE | G15: FALSE | H15: 6 | I15: 아슬아슬하게넣음, 중간에 병을 떨어트림,
B16: ACT | C16: 200 | D16: 1회차 | E16: TRUE | F16: TRUE | G16: TRUE | H16: 10
B17: ACT | C17: 200 | D17: 2회차 | E17: TRUE | F17: TRUE | G17: FALSE | H17: 6 | I17: 중간에 병을 떨어트림
B18: ACT | C18: 200 | D18: 3회차 | E18: TRUE | F18: TRUE | G18: TRUE | H18: 10
B19: ACT | C19: 200 | D19: 4회차 | E19: TRUE | F19: TRUE | G19: TRUE | H19: 10
B20: ACT | C20: 200 | D20: 5회차 | E20: TRUE | F20: TRUE | G20: FALSE | H20: 6 | I20: 중간에 병을 떨어트림
B21: Pi0 | C21: 50 | D21: 1회차 | E21: TRUE | F21: TRUE | G21: TRUE | H21: 10 | I21: 보정해서 성공함
B22: Pi0 | C22: 50 | D22: 2회차 | E22: TRUE | F22: TRUE | G22: TRUE | H22: 10
B23: Pi0 | C23: 50 | D23: 3회차 | E23: TRUE | F23: TRUE | G23: TRUE | H23: 10
B24: Pi0 | C24: 50 | D24: 4회차 | E24: TRUE | F24: TRUE | G24: TRUE | H24: 10 | I24: 병을 놓고 멈칫히다가 성공함, 병을 끓어서 성공함
B25: Pi0 | C25: 50 | D25: 5회차 | E25: TRUE | F25: TRUE | G25: FALSE | H25: 6 | I25: 무효 한 번 있음: 이미 목적지에 병이 있어 아예 작동 안했음. 병을 떨어트림.
B26: Pi0 | C26: 100 | D26: 1회차 | E26: TRUE | F26: TRUE | G26: TRUE | H26: 10 | I26: 병을 부딧혔지만 성공함
B27: Pi0 | C27: 100 | D27: 2회차 | E27: TRUE | F27: TRUE | G27: TRUE | H27: 10
B28: Pi0 | C28: 100 | D28: 3회차 | E28: TRUE | F28: TRUE | G28: FALSE | H28: 6 | I28: 병을 못넘
B29: Pi0 | C29: 100 | D29: 4회차 | E29: TRUE | F29: TRUE | G29: FALSE | H29: 6 | I29: 병을 다시 집으려했지만 실패함
B30: Pi0 | C30: 100 | D30: 5회차 | E30: TRUE | F30: TRUE | G30: FALSE | H30: 6 | I30: 병을 못넘
B31: Pi0 | C31: 200 | D31: 1회차 | E31: TRUE | F31: TRUE | G31: FALSE | H31: 6 | I31: 병을 잘 못 집음
B32: Pi0 | C32: 200 | D32: 2회차 | E32: FALSE | F32: FALSE | G32: FALSE | H32: =(E32="TRUE")*2+(F32="TRUE")*4+(G32="TRUE")*4 -> 0 | I32: 병을 못넘 2
B33: Pi0 | C33: 200 | D33: 3회차 | E33: FALSE | F33: FALSE | G33: FALSE | H33: =(E33="TRUE")*2+(F33="TRUE")*4+(G33="TRUE")*4 -> 0 | I33: 병을 못넘 2
B34: Pi0 | C34: 200 | D34: 4회차 | E34: TRUE | F34: TRUE | G34: FALSE | H34: 6 | I34: 그리퍼를 못 닫음
B35: Pi0 | C35: 200 | D35: 5회차 | E35: TRUE | F35: TRUE | G35: FALSE | H35: 6 | I35: 그리퍼를 못 닫음
B36: Pi0.5 | C36: 50 | D36: 1회차 | E36: FALSE | F36: FALSE | G36: FALSE | H36: =(E36="TRUE")*2+(F36="TRUE")*4+(G36="TRUE")*4 -> 0 | I36: 병을 집으려고 하지만 못 잡음 * 2
B37: Pi0.5 | C37: 50 | D37: 2회차 | E37: FALSE | F37: FALSE | G37: FALSE | H37: =(E37="TRUE")*2+(F37="TRUE")*4+(G37="TRUE")*4 -> 0 | I37: 병을 집으려고 하지만 못 잡음 * 2
B38: Pi0.5 | C38: 50 | D38: 3회차 | E38: FALSE | F38: FALSE | G38: FALSE | H38: =(E38="TRUE")*2+(F38="TRUE")*4+(G38="TRUE")*4 -> 0 | I38: 병을 집으려고 하지만 못 잡음 * 2
B39: Pi0.5 | C39: 50 | D39: 4회차 | E39: FALSE | F39: FALSE | G39: FALSE | H39: =(E39="TRUE")*2+(F39="TRUE")*4+(G39="TRUE")*4 -> 0 | I39: 병을 집으려고 하지만 못 잡음 * 2
B40: Pi0.5 | C40: 50 | D40: 5회차 | E40: FALSE | F40: FALSE | G40: FALSE | H40: =(E40="TRUE")*2+(F40="TRUE")*4+(G40="TRUE")*4 -> 0 | I40: 병을 집으려고 하지만 못 잡음 * 2
B41: Pi0.5 | C41: 100 | D41: 1회차 | E41: FALSE | F41: FALSE | G41: FALSE | H41: =(E41="TRUE")*2+(F41="TRUE")*4+(G41="TRUE")*4 -> 0 | I41: 아예 진동만함 * 2
B42: Pi0.5 | C42: 100 | D42: 2회차 | E42: FALSE | F42: FALSE | G42: FALSE | H42: =(E42="TRUE")*2+(F42="TRUE")*4+(G42="TRUE")*4 -> 0 | I42: 아예 진동만함 * 2
...

Sheet 밸브 조작
B2: VLA 모델 평가 — Raw Data [밸브 조작]
B3: 평가 기준 | 40초 내 완료: 2점 · 작업 성공: 4점 · 2회 연속 성공: 4점 · 총점: 10점 | 각 셀은 TRUE / FALSE 드롭다운에서 선택
B5: 모델 | C5: 데이터세트 크기 | D5: 시도 횟수 | E5: 180초 내 완료 | F5: 작업 성공 | G5: 2회 연속 성공 | H5: 총 점수 | I5: 비고
B6: ACT | C6: 50 | D6: 1회차 | E6: TRUE | F6: TRUE | G6: TRUE | H6: 10
B7: ACT | C7: 50 | D7: 2회차 | E7: TRUE | F7: TRUE | G7: TRUE | H7: 10 | I7: 살짝 돌릴때 버벅이는 것 같음
B8: ACT | C8: 50 | D8: 3회차 | E8: TRUE | F8: TRUE | G8: TRUE | H8: 10
B9: ACT | C9: 50 | D9: 4회차 | E9: TRUE | F9: TRUE | G9: FALSE | H9: 6 | I9: 밸브를 잘 못 집고 꺽음
B10: ACT | C10: 50 | D10: 5회차 | E10: TRUE | F10: TRUE | G10: TRUE | H10: 10
B11: ACT | C11: 100 | D11: 1회차 | E11: TRUE | F11: TRUE | G11: TRUE | H11: 10
B12: ACT | C12: 100 | D12: 2회차 | E12: TRUE | F12: TRUE | G12: TRUE | H12: 10
B13: ACT | C13: 100 | D13: 3회차 | E13: TRUE | F13: TRUE | G13: TRUE | H13: 10 | I13: 중간에 좀 멈춰있었음
B14: ACT | C14: 100 | D14: 4회차 | E14: TRUE | F14: TRUE | G14: TRUE | H14: 10
B15: ACT | C15: 100 | D15: 5회차 | E15: TRUE | F15: TRUE | G15: FALSE | H15: 6 | I15: 밸브를 찍음, 모터 부하로 로봇 재시가함
B16: ACT | C16: 200 | D16: 1회차 | E16: TRUE | F16: TRUE | G16: TRUE | H16: 10
B17: ACT | C17: 200 | D17: 2회차 | E17: TRUE | F17: TRUE | G17: TRUE | H17: 10
B18: ACT | C18: 200 | D18: 3회차 | E18: TRUE | F18: TRUE | G18: TRUE | H18: 10
B19: ACT | C19: 200 | D19: 4회차 | E19: TRUE | F19: TRUE | G19: TRUE | H19: 10
B20: ACT | C20: 200 | D20: 5회차 | E20: TRUE | F20: TRUE | G20: TRUE | H20: 10 | I20: 전반적으로 밸브를 더 잘 돌리는 듯 함
B21: Pi0 | C21: 50 | D21: 1회차 | E21: TRUE | F21: TRUE | G21: TRUE | H21: 10
B22: Pi0 | C22: 50 | D22: 2회차 | E22: TRUE | F22: TRUE | G22: TRUE | H22: 10
B23: Pi0 | C23: 50 | D23: 3회차 | E23: TRUE | F23: TRUE | G23: TRUE | H23: 10
B24: Pi0 | C24: 50 | D24: 4회차 | E24: TRUE | F24: TRUE | G24: FALSE | H24: 6 | I24: 무효 1번, 모델이 이미 밸브가 돌아가 있음을 인지함, 밸브 위치를 잘 못 인식함
B25: Pi0 | C25: 50 | D25: 5회차 | E25: FALSE | F25: FALSE | G25: FALSE | H25: =(E25="TRUE")*2+(F25="TRUE")*4+(G25="TRUE")*4 -> 0 | I25: 밸브 위치를 잘 못 인식함 * 2
B26: Pi0 | C26: 100 | D26: 1회차 | E26: TRUE | F26: TRUE | G26: TRUE | H26: 10
B27: Pi0 | C27: 100 | D27: 2회차 | E27: TRUE | F27: TRUE | G27: FALSE | H27: 6 | I27: 밸브를 찍음
B28: Pi0 | C28: 100 | D28: 3회차 | E28: TRUE | F28: TRUE | G28: TRUE | H28: 10
B29: Pi0 | C29: 100 | D29: 4회차 | E29: FALSE | F29: FALSE | G29: FALSE | H29: =(E29="TRUE")*2+(F29="TRUE")*4+(G29="TRUE")*4 -> 0 | I29: 밸브 근처에서 머뭇거림 * 2
B30: Pi0 | C30: 100 | D30: 5회차 | E30: TRUE | F30: TRUE | G30: FALSE | H30: 6 | I30: 밸브 근처에서 머뭇거림
B31: Pi0 | C31: 200 | D31: 1회차 | E31: TRUE | F31: TRUE | G31: TRUE | H31: 10
B32: Pi0 | C32: 200 | D32: 2회차 | E32: TRUE | F32: TRUE | G32: TRUE | H32: 10
B33: Pi0 | C33: 200 | D33: 3회차 | E33: TRUE | F33: TRUE | G33: TRUE | H33: 10
B34: Pi0 | C34: 200 | D34: 4회차 | E34: TRUE | F34: TRUE | G34: TRUE | H34: 10
B35: Pi0 | C35: 200 | D35: 5회차 | E35: TRUE | F35: TRUE | G35: TRUE | H35: 10
B36: Pi0.5 | C36: 50 | D36: 1회차 | E36: FALSE | F36: FALSE | G36: FALSE | H36: =(E36="TRUE")*2+(F36="TRUE")*4+(G36="TRUE")*4 -> 0 | I36: 모션이 튐 *2
B37: Pi0.5 | C37: 50 | D37: 2회차 | E37: FALSE | F37: FALSE | G37: FALSE | H37: =(E37="TRUE")*2+(F37="TRUE")*4+(G37="TRUE")*4 -> 0 | I37: 밸브를 못 잡음 * 2
B38: Pi0.5 | C38: 50 | D38: 3회차 | E38: FALSE | F38: FALSE | G38: FALSE | H38: =(E38="TRUE")*2+(F38="TRUE")*4+(G38="TRUE")*4 -> 0 | I38: 밸브를 못 잡음 * 2
B39: Pi0.5 | C39: 50 | D39: 4회차 | E39: FALSE | F39: FALSE | G39: FALSE | H39: =(E39="TRUE")*2+(F39="TRUE")*4+(G39="TRUE")*4 -> 0 | I39: 노파심에 카메라 재부팅함. 밸브를 못 잡음 * 2
B40: Pi0.5 | C40: 50 | D40: 5회차 | E40: FALSE | F40: FALSE | G40: FALSE | H40: =(E40="TRUE")*2+(F40="TRUE")*4+(G40="TRUE")*4 -> 0 | I40: 밸브를 못 잡음 * 2
B41: Pi0.5 | C41: 100 | D41: 1회차 | E41: TRUE | F41: TRUE | G41: TRUE | H41: 10
B42: Pi0.5 | C42: 100 | D42: 2회차 | E42: TRUE | F42: TRUE | G42: FALSE | H42: 10 | I42: 간신히 넣음 밸브를 찍음
...

Sheet Pouring
B2: VLA 모델 평가 — Raw Data [Pouring]
B3: 평가 기준 | 60초 내 완료: 2점 · 작업 성공: 4점 · 2회 연속 성공: 4점 · 총점: 10점 | 각 셀은 TRUE / FALSE 드롭다운에서 선택
B5: 모델 | C5: 데이터세트 크기 | D5: 시도 횟수 | E5: 180초 내 완료 | F5: 작업 성공 | G5: 2회 연속 성공 | H5: 총 점수 | I5: 비고
B6: ACT | C6: 50 | D6: 1회차 | E6: FALSE | F6: FALSE | G6: FALSE | H6: =(E6="TRUE")*2+(F6="TRUE")*4+(G6="TRUE")*4 -> 0 | I6: 아예 못 집음 2
B7: ACT | C7: 50 | D7: 2회차 | E7: FALSE | F7: TRUE | G7: FALSE | H7: 4 | I7: 아예 못 집음, 병을 반납 못함
B8: ACT | C8: 50 | D8: 3회차 | E8: FALSE | F8: TRUE | G8: FALSE | H8: 4 | I8: 병을 반납 못함, 아예 못 집음
B9: ACT | C9: 50 | D9: 4회차 | E9: FALSE | F9: FALSE | G9: FALSE | H9: =(E9="TRUE")*2+(F9="TRUE")*4+(G9="TRUE")*4 -> 0 | I9: 아예 못 집음 2
B10: ACT | C10: 50 | D10: 5회차 | E10: FALSE | F10: FALSE | G10: FALSE | H10: =(E10="TRUE")*2+(F10="TRUE")*4+(G10="TRUE")*4 -> 0 | I10: 아예 못 집음 2
B11: ACT | C11: 100 | D11: 1회차 | E11: FALSE | F11: TRUE | G11: FALSE | H11: 4 | I11: 병을 집기만 함, 병을 반납 못함
B12: ACT | C12: 100 | D12: 2회차 | E12: FALSE | F12: FALSE | G12: FALSE | H12: =(E12="TRUE")*2+(F12="TRUE")*4+(G12="TRUE")*4 -> 0 | I12: 시작에 머뭇거리고 병을 못 뺌, 아예 못 집음
B13: ACT | C13: 100 | D13: 3회차 | E13: FALSE | F13: FALSE | G13: FALSE | H13: =(E13="TRUE")*2+(F13="TRUE")*4+(G13="TRUE")*4 -> 0 | I13: 갑자기 원점으로 돌아감 2
B14: ACT | C14: 100 | D14: 4회차 | E14: FALSE | F14: FALSE | G14: FALSE | H14: =(E14="TRUE")*2+(F14="TRUE")*4+(G14="TRUE")*4 -> 0 | I14: 갑자기 원점으로 돌아감, 병을 못 뺌,
B15: ACT | C15: 100 | D15: 5회차 | E15: FALSE | F15: FALSE | G15: FALSE | H15: =(E15="TRUE")*2+(F15="TRUE")*4+(G15="TRUE")*4 -> 0 | I15: 병을 못 집음. 갑자기 원점으로 돌아감
B16: ACT | C16: 200 | D16: 1회차 | E16: FALSE | F16: FALSE | G16: FALSE | H16: =(E16="TRUE")*2+(F16="TRUE")*4+(G16="TRUE")*4 -> 0 | I16: 병을 못 듬 2
B17: ACT | C17: 200 | D17: 2회차 | E17: TRUE | F17: TRUE | G17: FALSE | H17: 6 | I17: 병을 못 듬 걱정되도 인내심 가져야함
B18: ACT | C18: 200 | D18: 3회차 | E18: TRUE | F18: TRUE | G18: TRUE | H18: 10 | I18: 갑자기 잘함!
B19: ACT | C19: 200 | D19: 4회차 | E19: TRUE | F19: TRUE | G19: TRUE | H19: 10 | I19: 무효1번: 카메라선 손상, 깔때기 방해가 있어도 정상 수행함
B20: ACT | C20: 200 | D20: 5회차 | E20: TRUE | F20: TRUE | G20: FALSE | H20: 6 | I20: 병을 못 넘
B21: Pi0 | C21: 50 | D21: 1회차 | E21: FALSE | F21: FALSE | G21: FALSE | H21: =(E21="TRUE")*2+(F21="TRUE")*4+(G21="TRUE")*4 -> 0 | I21: 병을 못 집음 병을 놓침
B22: Pi0 | C22: 50 | D22: 2회차 | E22: FALSE | F22: FALSE | G22: FALSE | H22: =(E22="TRUE")*2+(F22="TRUE")*4+(G22="TRUE")*4 -> 0 | I22: 병을 못 집음 2
B23: Pi0 | C23: 50 | D23: 3회차 | E23: FALSE | F23: FALSE | G23: FALSE | H23: =(E23="TRUE")*2+(F23="TRUE")*4+(G23="TRUE")*4 -> 0 | I23: 원점으로 돌아감, 집었지만 못 부음
B24: Pi0 | C24: 50 | D24: 4회차 | E24: FALSE | F24: FALSE | G24: FALSE | H24: =(E24="TRUE")*2+(F24="TRUE")*4+(G24="TRUE")*4 -> 0 | I24: 다 못 부음 병을 못 집음
B25: Pi0 | C25: 50 | D25: 5회차 | E25: FALSE | F25: FALSE | G25: FALSE | H25: =(E25="TRUE")*2+(F25="TRUE")*4+(G25="TRUE")*4 -> 0 | I25: 병을 못 이동시킴
B26: Pi0 | C26: 100 | D26: 1회차 | E26: FALSE | F26: FALSE | G26: FALSE | H26: =(E26="TRUE")*2+(F26="TRUE")*4+(G26="TRUE")*4 -> 0 | I26: 다 못 부음, 중간에 걸림
B27: Pi0 | C27: 100 | D27: 2회차 | E27: FALSE | F27: FALSE | G27: FALSE | H27: =(E27="TRUE")*2+(F27="TRUE")*4+(G27="TRUE")*4 -> 0 | I27: 중간에 복귀함, 다 부었지만 계속 부음
B28: Pi0 | C28: 100 | D28: 3회차 | E28: FALSE | F28: FALSE | G28: FALSE | H28: =(E28="TRUE")*2+(F28="TRUE")*4+(G28="TRUE")*4 -> 0 | I28: 병을 못 집음, 중간에 복귀함
B29: Pi0 | C29: 100 | D29: 4회차 | E29: FALSE | F29: TRUE | G29: FALSE | H29: 4 | I29: 다 부었지만 계속 부어 복귀 못함, 병을 못 넣음
B30: Pi0 | C30: 100 | D30: 5회차 | E30: FALSE | F30: TRUE | G30: FALSE | H30: 4 | I30: 무효 1번, 다 부었지만 계속 부음,
B31: Pi0 | C31: 200 | D31: 1회차 | E31: TRUE | F31: TRUE | G31: FALSE | H31: 6 | I31: 병을 못 집음
B32: Pi0 | C32: 200 | D32: 2회차 | E32: TRUE | F32: TRUE | G32: TRUE | H32: 10
B33: Pi0 | C33: 200 | D33: 3회차 | E33: TRUE | F33: TRUE | G33: FALSE | H33: 6 | I33: 병을 좀 세게넘, 병을 반납 못함
B34: Pi0 | C34: 200 | D34: 4회차 | E34: FALSE | F34: FALSE | G34: FALSE | H34: =(E34="TRUE")*2+(F34="TRUE")*4+(G34="TRUE")*4 -> 0 | I34: 병을 못 집음 2
B35: Pi0 | C35: 200 | D35: 5회차 | E35: FALSE | F35: TRUE | G35: FALSE | H35: 6 | I35: 병을 반납 못함, 다 부었지만 계속 부어 복귀 못함
B36: Pi0.5 | C36: 50 | D36: 1회차 | E36: FALSE | F36: FALSE | G36: FALSE | H36: =(E36="TRUE")*2+(F36="TRUE")*4+(G36="TRUE")*4 -> 0 | I36: 병을 놓침, 병을 밈
B37: Pi0.5 | C37: 50 | D37: 2회차 | E37: FALSE | F37: FALSE | G37: FALSE | H37: =(E37="TRUE")*2+(F37="TRUE")*4+(G37="TRUE")*4 -> 0 | I37: 주변을 침 병을 누름
B38: Pi0.5 | C38: 50 | D38: 3회차 | E38: FALSE | F38: FALSE | G38: FALSE | H38: =(E38="TRUE")*2+(F38="TRUE")*4+(G38="TRUE")*4 -> 0 | I38: 병을 누름 병을 못 잡음
B39: Pi0.5 | C39: 50 | D39: 4회차 | E39: FALSE | F39: FALSE | G39: FALSE | H39: =(E39="TRUE")*2+(F39="TRUE")*4+(G39="TRUE")*4 -> 0 | I39: 지금 부터 녹화함 ㅠ, 병을 누름 원점으로돌아가다 병을 찍음
B40: Pi0.5 | C40: 50 | D40: 5회차 | E40: FALSE | F40: FALSE | G40: FALSE | H40: =(E40="TRUE")*2+(F40="TRUE")*4+(G40="TRUE")*4 -> 0 | I40: 병을 어예 못 잡음 2
B41: Pi0.5 | C41: 100 | D41: 1회차 | E41: FALSE | F41: FALSE | G41: FALSE | H41: =(E41="TRUE")*2+(F41="TRUE")*4+(G41="TRUE")*4 -> 0 | I41: 처음보는 테크닉을 집음. 근데 성공 못함., 병을 집지만 들진 못함
B42: Pi0.5 | C42: 100 | D42: 2회차 | E42: FALSE | F42: FALSE | G42: FALSE | H42: =(E42="TRUE")*2+(F42="TRUE")*4+(G42="TRUE")*4 -> 0 | I42: 병을 세게임, 병을 집었지만 못 놓았음
...
